{
    "CVE_data_meta": {
        "ASSIGNER": "cve@mitre.org",
        "ID": "CVE-2022-48560",
        "STATE": "PUBLIC"
    },
    "affects": {
        "vendor": {
            "vendor_data": [
                {
                    "product": {
                        "product_data": [
                            {
                                "product_name": "n/a",
                                "version": {
                                    "version_data": [
                                        {
                                            "version_value": "n/a"
                                        }
                                    ]
                                }
                            }
                        ]
                    },
                    "vendor_name": "n/a"
                }
            ]
        }
    },
    "data_format": "MITRE",
    "data_type": "CVE",
    "data_version": "4.0",
    "description": {
        "description_data": [
            {
                "lang": "eng",
                "value": "A use-after-free exists in Python through 3.9 via heappushpop in heapq."
            }
        ]
    },
    "problemtype": {
        "problemtype_data": [
            {
                "description": [
                    {
                        "lang": "eng",
                        "value": "n/a"
                    }
                ]
            }
        ]
    },
    "references": {
        "reference_data": [
            {
                "url": "https://bugs.python.org/issue39421",
                "refsource": "MISC",
                "name": "https://bugs.python.org/issue39421"
            }
        ]
    }
}