{
    "data_version": "4.0",
    "data_type": "CVE",
    "data_format": "MITRE",
    "CVE_data_meta": {
        "ID": "CVE-2025-4516",
        "ASSIGNER": "cna@python.org",
        "STATE": "PUBLIC"
    },
    "description": {
        "description_data": [
            {
                "lang": "eng",
                "value": "There is an issue in CPython when using `bytes.decode(\"unicode_escape\", error=\"ignore|replace\")`. If you are not using the \"unicode_escape\" encoding or an error handler your usage is not affected. To work-around this issue you may stop using the error= handler and instead wrap the bytes.decode() call in a try-except catching the DecodeError."
            }
        ]
    },
    "problemtype": {
        "problemtype_data": [
            {
                "description": [
                    {
                        "lang": "eng",
                        "value": "CWE-416 Use After Free",
                        "cweId": "CWE-416"
                    }
                ]
            }
        ]
    },
    "affects": {
        "vendor": {
            "vendor_data": [
                {
                    "vendor_name": "Python Software Foundation",
                    "product": {
                        "product_data": [
                            {
                                "product_name": "CPython",
                                "version": {
                                    "version_data": [
                                        {
                                            "version_affected": "<",
                                            "version_name": "0",
                                            "version_value": "3.14.0b1"
                                        }
                                    ]
                                }
                            }
                        ]
                    }
                }
            ]
        }
    },
    "references": {
        "reference_data": [
            {
                "url": "https://github.com/python/cpython/issues/133767",
                "refsource": "MISC",
                "name": "https://github.com/python/cpython/issues/133767"
            },
            {
                "url": "https://github.com/python/cpython/pull/129648",
                "refsource": "MISC",
                "name": "https://github.com/python/cpython/pull/129648"
            },
            {
                "url": "https://mail.python.org/archives/list/security-announce@python.org/thread/L75IPBBTSCYEF56I2M4KIW353BB3AY74/",
                "refsource": "MISC",
                "name": "https://mail.python.org/archives/list/security-announce@python.org/thread/L75IPBBTSCYEF56I2M4KIW353BB3AY74/"
            },
            {
                "url": "https://github.com/python/cpython/commit/69b4387f78f413e8c47572a85b3478c47eba8142",
                "refsource": "MISC",
                "name": "https://github.com/python/cpython/commit/69b4387f78f413e8c47572a85b3478c47eba8142"
            },
            {
                "url": "https://github.com/python/cpython/commit/9f69a58623bd01349a18ba0c7a9cb1dad6a51e8e",
                "refsource": "MISC",
                "name": "https://github.com/python/cpython/commit/9f69a58623bd01349a18ba0c7a9cb1dad6a51e8e"
            }
        ]
    },
    "generator": {
        "engine": "Vulnogram 0.2.0"
    },
    "source": {
        "discovery": "UNKNOWN"
    }
}